SampleOutputSPSC/sample_vwap_5.txt
XBUY: 16.5865
NRGX: 20.4506
CFG-D: 25.1019
ZYNE: 5.0602
ZYME: 15.2389
ZXZZT: 6.6666
ZWZZT: 4.8333
ZVZZT: 9.9888
ZUO: 21.2239
ZUMZ: 24.9267
ZTS: 85.2219
ZTR: 9.7628
ZTO: 16.9557
ZSL: 35.2948
ZSAN: 2.089
ZS: 45.4283
ZROZ: 74.7999
ZOM: 0.6443
ZNWAA: 1.5066
ZNH: 32.3161
ZNGA: 4.4809
ZN: 0.481
ZMLP: 9.0533
ZLAB: 26.8908
ZKIN: 1.55
ZJZZT: 6.6666
ZIXI: 7.4968
ZIV: 66.5252
ZIOP: 2.0579
ZION: 48.3037
ZGNX: 41.6584
ZG: 32.8082
ZFGN: 4.2262
ZF: 8.7571
ZEUS: 18.6284
ZEN: 65.2432
ZEAL: 14.3166
ZDGE: 1.2933
ZBRA: 170.74
ZBIO: 15.954
ZBH: 107.2961
ZB-G: 22.61
ZAYO: 26.6962
ZAGG: 11.1709
Z: 33.0552
YYY: 17.2537
YY: 67.1049
YUMC: 35.7292
YUMA: 0.1136
YUM: 93.1914
YTRA: 5.1024
YTEN: 0.6532
YRIV: 2.0733
YRD: 10.9679
YRCW: 5.7762
YPF: 15.7255
YORW: 30.4287
YOGA: 0.528
YNDX: 32.8739
YMLP: 19.35
YMLI: 8.2466
YMAB: 19.6777
YLDE: 3.6192
YINN: 21.3311
YIN: 6.9944
YI: 8.6164
YGYI: 7.3532
YEXT: 14.9592
YETI: 16.7341
YELP: 36.0924
YCS: 49.4224
YANG: 52.7716
Y: 621.9127
XYL: 70.525
XYF: 5.36
XXII: 2.2768
XWEB: 84.9333
XTN: 39.6432
XTL: 65.0421
XT: 35.6077
XSW: 72.4896
XSPA: 0.1814
XSOE: 18.4399
XSLV: 45.6361
XSD: 68.9045
XRX: 27.7999
XRT: 43.945
XRLV: 22.7399
XRAY: 41.1199
XPP: 65.3692
XPO: 61.4951
XPH: 38.4567
XPER: 21.0605
XOP: 30.514
XONE: 8.3529
XON: 7.4914
XOMA: 11.9708
XOM: 71.8378
XOG: 4.0681
XNTK: 57.0587
XNET: 3.405
XNCR: 32.4831
XMLV: 41.4519
XME: 29.9678
XLY: 106.8186
XLV: 88.7701
XLU: 53.4131
XLRN: 39.94
XLRE: 33.8926
XLP: 52.198
XLNX: 111.1068
XLK: 65.5084
XLI: 70.7693
XLG: 185.724
XLF: 25.8469
XLE: 62.8604
XLC: 43.7512
XLB: 53.8411
XKST: 26.5
XITK: 92.5633
XINA: 0.7866
XIN: 4.7544
XHS: 30.7221
XHR: 18.627
XHE: 71.8581
XHB: 35.5631
XGTI: 0.3695
XFLT: 8.4193
XES: 10.8763
XERS: 14.9764
XENT: 28.9008
XENE: 8.0336
XELA: 3.6014
XEL: 50.8925
XEC: 75.7623
XCEM: 17.2466
XBIT: 6.4442
XBIO: 2.1132
XBI: 80.5389
XAR: 88.5505
XAN: 10.5098
X: 22.1442
WYY: 0.4399
WYNN: 119.7071
WYND: 42.2746
WY: 26.0952
WWW: 33.87
WWR: 0.1431
WWE: 81.9372
WWD: 85.7626
WVE: 35.4637
WUBA: 61.0658
WU: 18.2439
WTW: 31.9222
WTTR: 8.573
WTT: 31.1666
WTS: 73.1056
WTRH: 12.1632
WTR: 34.2277
WTMF: 25.5999
WTM: 893.4132
WTIU: 13.9254
WTID: 9.605
WTI: 5.0623
WTFCM: 18.3433
WTFC: 72.5735
WTER: 3.4998
WTBA: 21.5905
WSTL: 1.7854
WST: 105.475
WSR: 14.2908
WSO: 146.1622
WSM: 52.4306
WSFS: 41.9627
WSC: 10.1237
WSBF: 16.975
WSBC: 41.4736
WRTC: 2.6397
WRN: 0.7176
WRLSR: 0.2539
WRLS: 6.7999
WRLD: 110.4044
WRK: 41.266
WRI: 28.4174
WRE: 25.137
WRD: 17.1461
WRB-E: 23.9759
WRB-D: 16.3299
WRB-C: 25.2104
WRB-B: 24.5272
WRB: 77.0062
WPX: 12.2533
WPS: 35.7751
WPRT: 1.4804
WPP: 57.699
WPM: 20.212
WPG-H: 10.4999
WPG: 5.7514
WPC: 73.9239
WP: 83.6588
WOW: 7.2407
WOR: 36.6467
WOOD: 66.0194
WNS: 48.9154
WNEB: 9.2793
WNC: 13.9465
WMT: 94.8809
WMS: 25.0134
WMK: 47.693
WMGIZ: 0.0046
WMGI: 29.7041
WMC: 9.577
WMB: 26.852
WM: 94.4742
WLTW: 159.8774
WLL: 28.6811
WLKP: 23.3877
WLK: 76.0199
WLH: 34.8896
WLFC: 30.2161
WLDN: 33.3708
WKHS: 0.8851
WK: 39.2058
WIX: 105.4957
WIW: 10.4946
WIT: 5.4814
WISA: 3.0933
WIRE: 52.2326
WIP: 35.9197
WINS: 22.4786
WING: 66.1489
WINA: 152.0106
WIN: 2.8592
WILC: 5.4266
WIL: 42.9666
WIFI: 22.7982
WIA: 10.9318
WHR: 130.883
WHLRW: 0.0066
WHLRP: 10.2696
WHLRD: 11.8366
WHLR: 1.6626
WHLM: 3.4999
WHG: 26.0604
WHF: 13.6765
WHD: 32.3936
WH: 49.6053
WGP: 32.6133
WGO: 29.3494
WFT: 0.6407
WFHY: 32.9333
WFE-A: 22.8599
WFC-Y: 16.6666
WFC-X: 22.3759
WFC-W: 23.5535
WFC-V: 25.8143
WFC-T: 17.1933
WFC-R: 18.4815
WFC-Q: 25.3742
WFC-P: 21.8105
WFC-O: 23.0381
WFC-N: 21.5889
WFC: 49.8776
WEYS: 27.2287
WEX: 157.2548
WETF: 6.4597
WES: 49.7891
WERN: 33.0426
WEN: 17.3155
WELL-I: 67.2925
WELL: 76.5541
WEC: 70.9461
WEBK: 19.7333
WEAT: 6.01
WEA: 12.4629
WDRW: 30.5955
WDR: 16.8231
WDIV: 65.36
WDFC: 178.3547
WDC: 42.8806
WDAY: 169.2201
WD: 47.6958
WCN: 81.2232
WCHN: 16.8933
WCG: 275.1942
WCC: 53.4752
WBT: 13.8037
WBS-F: 22.69
WBS: 56.0014
WBK: 18.1756
WBIY: 15.8999
WBIR: 15.4666
WBII: 16.1333
WBIH: 21.9733
WBIG: 15.5599
WBID: 20.95
WBIB: 21.24
WBC: 112.9099
WBAI: 14.3018
WBA: 71.5711
WB: 58.1464
WATT: 7.3453
WAT: 229.9106
WASH: 51.6046
WAL: 45.5648
WAIR: 8.0788
WAGE: 30.7176
WAFD: 29.1856
WABC: 62.8941
WAB: 68.4593
WAAS: 20.9784
W: 107.4808
VZA: 25.3286
VZ: 53.1902
VYMI: 59.6142
VYM: 81.6192
VYGR: 10.4944
VXZB: 20.2113
VXXB: 38.1961
VXUS: 50.3198
VXRT: 1.6672
VXF: 109.3315
VWOB: 76.3898
VWO: 40.7176
VVV: 22.3659
VVUS: 4.7215
VVR: 3.7135
VVI: 51.4163
VVC: 72.2287
VV: 122.0474
VUZI: 4.0327
VUSE: 30.5733
VUG: 143.4415
VTWV: 68.201
VTWO: 117.6204
VTWG: 133.1674
VTVT: 2.7203
VTV: 103.4486
VTSI: 3.5985
VTR: 63.8866
VTNR: 1.3168
VTN: 12.6228
VTL: 0.1944
VTIP: 48.0475
VTI: 136.151
VTHR: 111.2099
VTGN: 1.5325
VTEB: 50.9619
VTC: 77.227
VTA: 10.6999
VT: 69.7235
VSTO: 10.311
VSTM: 3.1091
VST: 24.8735
VSS: 100.6399
VSMV: 28.0687
VSM: 37.0047
VSLR: 4.0112
VSI: 4.5694
VSH: 19.0332
VSGX: 31.8266
VSEC: 32.1256
VSAT: 61.3722
VRTX: 185.5702
VRTV: 33.0424
VRTU: 47.6347
VRTSP: 76.0257
VRTS: 87.4456
VRSN: 165.7601
VRSK: 116.874
VRS: 24.6994
VRRM: 10.2536
VRP: 22.4785
VRNT: 46.9212
VRNS: 57.408
VRNA: 5.2724
VRML: 0.6858
VRIG: 17.8434
VREX: 27.9791
VRCA: 11.9294
VRAY: 6.9156
VRA: 8.9398
VPV: 12.0451
VPU: 119.2873
VPL: 64.4689
VPG: 31.9562
VOYA: 45.8497
VOXX: 5.1775
VOX: 78.277
VOT: 130.7978
VOOV: 104.4526
VOOG: 138.6663
VOO: 244.0073
VONV: 103.4629
VONG: 143.2458
VONE: 121.8051
VOE: 103.286
VOD: 17.8319
VOC: 3.6181
VO: 150.3667
VNTR: 4.6027
VNRX: 2.5433
VNQI: 56.8476
VNQ: 82.3429
VNOM: 30.4285
VNO-M: 15.1533
VNO-L: 21.3263
VNO: 68.5493
VNM: 15.7493
VNLA: 49.344
VNET: 8.7076
VNE: 29.2451
VNDA: 28.3346
VNCE: 11.6217
VMW: 145.8277
VMOT: 16.7666
VMO: 11.5919
VMM: 12.17
VMI: 125.9698
VMC: 101.8453
VMBS: 51.6567
VLYPP: 24.6853
VLYPO: 23.8888
VLY: 10.2652
VLUE: 77.8177
VLT: 13.7657
VLRX: 0.3978
VLRS: 7.4278
VLO: 82.3485
VLGEA: 25.3991
VKTXW: 2.2182
VKTX: 8.0397
VKQ: 11.7646
VKI: 8.9508
VJET: 1.3866
VIXY: 31.402
VIXM: 22.4469
VIVO: 16.0323
VIVE: 1.1848
VIV: 12.9056
VISI: 2.4666
VIS: 119.7817
VIRT: 25.4544
VIRC: 2.8231
VIPS: 7.4681
VIOV: 116.4129
VIOT: 7.3195
VIOO: 127.0724
VIOG: 99.3866
VIIX: 15.337
VIGI: 60.7635
VIG: 102.953
VIDI: 16.3553
VICR: 40.2588
VICL: 0.9555
VICI: 21.4685
VIAV: 10.7669
VIAB: 28.3842
VIA: 32.74
VHT: 166.3853
VHI: 3.244
VHC: 4.8724
VGZ: 0.4427
VGT: 177.5813
VGSH: 60.1155
VGR: 10.5277
VGM: 10.2056
VGLT: 74.3433
VGK: 51.5821
VGIT: 63.3808
VGI: 11.5857
VG: 9.031
VFMV: 52.5599
VFMF: 48.2733
VFH: 64.8761
VFC: 83.9356
VEU: 48.5281
VET: 23.9427
VERU: 1.4914
VERI: 5.4156
VER-F: 16.7933
VER: 8.021
VEON: 2.4637
VEGI: 18.8058
VEEV: 107.0416
VEDL: 11.0677
VECO: 9.812
VEC: 24.1388
VEACW: 0.4417
VEAC: 10.1332
VEA: 39.5796
VDE: 85.0229
VDC: 135.473
VCYT: 17.5482
VCV: 11.1034
VCTR: 10.5677
VCSH: 78.648
VCRA: 39.7564
VCR: 161.7853
VCLT: 87.2245
VCIT: 84.3356
VCF: 9.1999
VCEL: 39.0986
VC: 75.0875
VBTX: 26.3737
VBR: 125.6837
VBND: 47.67
VBLT: 1.3027
VBK: 165.8763
VBIV: 1.6402
VBF: 17.6067
VB: 144.164
VAW: 119.4267
VAR: 131.2274
VAPO: 16.4713
VAM: 20.7266
VALU: 18.9866
VALQ: 25.1869
VALE: 12.359
VAC: 87.3212
V: 136.2776
UZC: 16.6266
UZB: 22.2055
UZA: 24.5266
UYM: 36.3466
UYG: 34.431
UXIN: 3.4666
UWT: 14.1374
UWN: 2.3824
UWM: 62.1092
UVXY: 59.1092
UVV: 57.2986
UVSP: 23.7504
UVE: 37.768
UUUU+: 0.8666
UUUU: 2.8862
UUU: 1.191
UUP: 25.4784
UTX: 118.4618
UTSL: 26.497
UTSI: 3.402
UTMD: 89.5826
UTL: 48.4983
UTI: 3.3728
UTHR: 115.5621
UTG: 30.3115
UTF: 22.9525
UTES: 22.8799
USX: 7.3588
USWSW: 0.67
USWS: 7.4485
USVM: 28.9003
UST: 36.9599
USRT: 36.7211
USPH: 106.2483
USOU: 25.737
USOI: 21.63
USOD: 6.5686
USO: 11.4172
USNA: 115.6847
USMV: 54.6549
USMF: 18.5133
USM: 55.961
USLV: 79.5048
USLB: 29.4694
USL: 13.9053
USIG: 53.591
USHY: 31.7658
USG: 43.1231
USFR: 21.5568
USFD: 34.2864
USEQ: 17.4266
USEG: 0.8873
USDU: 17.9399
USDP: 10.7507
USD: 28.511
USCR: 37.3101
USCI: 32.2838
USB-P: 23.9302
USB-O: 22.6324
USB-M: 26.2101
USB-H: 19.415
USB: 51.0053
USAU: 0.9987
USAT: 5.6474
USAS: 1.6054
USAP: 17.8141
USAK: 18.3927
USAC: 15.0994
USA: 5.7306
URTY: 64.1226
URTH: 81.2417
UROV: 8.8669
URI: 123.6272
URGN: 40.5814
URG: 0.6391
URE: 67.8571
URBN: 32.0334
URA: 12.6337
UQM: 1.6496
UPWK: 18.9072
UPV: 28.3266
